<?xml version="1.0" ?>
<robot name="amr" xmlns:xacro="http://www.ros.org/wiki/xacro">

<xacro:include filename="$(find amr_description)/urdf/materials.xacro" />
<xacro:include filename="$(find amr_description)/urdf/amr.trans" />
<xacro:include filename="$(find amr_description)/urdf/amr.gazebo" />
<link name="base_link">
  <inertial>
    <origin xyz="0.0 0.0 +0.125" rpy="0 0 0"/>
    <mass value="5.268945875000281"/>
    <!-- <mass value="0.0"/> -->
    <inertia ixx="0.123547" iyy="0.255706" izz="0.335967" ixy="0.0" iyz="0.0" ixz="-5e-06"/>
  </inertial>
  <visual>
    <origin xyz="-0.240 0.2 -0.125" rpy="0 0 0"/>
    <geometry>
      <mesh filename="package://amr_description/meshes/base_link1.stl" scale="0.001 0.001 0.001"/>
    </geometry>
    <material name="silver"/>
  </visual>
  <collision>
    <origin xyz="-0.240 0.2 -0.125" rpy="0 0 0"/>
    <geometry>
      <mesh filename="package://amr_description/meshes/base_link1.stl" scale="0.001 0.001 0.001"/>
    </geometry>
  </collision>
</link>

<link name="right_wheel_link">
  <inertial>
    <origin xyz="-1.3948845251077202e-07 -0.015000027249437387 3.997817098477796e-07" rpy="0 0 0"/>
    <mass value="0.4794196053084167"/>
    <inertia ixx="0.000114" iyy="0.000156" izz="0.000114" ixy="0.0" iyz="-0.0" ixz="0.0"/>
  </inertial>
  <visual>
    <origin xyz="-0.245 0.365 -0.1520" rpy="0 0 0"/>
    <geometry>
      <mesh filename="package://amr_description/meshes/link_1_1.stl" scale="0.001 0.001 0.001"/>
    </geometry>
    <material name="silver"/>
  </visual>
  <collision>
    <origin xyz="-0.245 0.365 -0.1520" rpy="0 0 0"/>
    <geometry>
      <mesh filename="package://amr_description/meshes/link_1_1.stl" scale="0.001 0.001 0.001"/>
    </geometry>
  </collision>
</link>

<link name="left_wheel_link">
  <inertial>
    <origin xyz="-1.394884518446382e-07 0.014999972750515497 3.99781715315628e-07" rpy="0 0 0"/>
    <mass value="0.4794196053084167"/>
    <inertia ixx="0.000114" iyy="0.000156" izz="0.000114" ixy="0.0" iyz="0.0" ixz="0.0"/>
  </inertial>
  <visual>
  <origin xyz="-0.2425 0.005 -0.155" rpy="0 0 0"/>
    <geometry>
      <mesh filename="package://amr_description/meshes/link_2_1.stl" scale="0.001 0.001 0.001"/>
    </geometry>
    <material name="silver"/>
  </visual>
  <collision>
    <origin xyz="-0.2425 0.005 -0.155" rpy="0 0 0"/>
    <geometry>
      <mesh filename="package://amr_description/meshes/link_2_1.stl" scale="0.001 0.001 0.001"/>
    </geometry>
  </collision>
</link>

<link name="laser_frame">
  <visual>
    <geometry>
      <cylinder radius="0.05" length="0.04"/>
    </geometry>
    <material name="red"></material>
    <collision>
        <geometry>
            <cylinder radius="0.05" length="0.04"/>
        </geometry>
    </collision>
  </visual>
</link>


<joint name="right_wheel_joint" type="continuous">
  <origin xyz="0.002 -0.165 0.028" rpy="0 0 0"/>
  <parent link="base_link"/>
  <child link="right_wheel_link"/>
  <axis xyz="-0.0 -1.0 -0.0"/>
</joint>

<joint name="left_wheel_joint" type="continuous">
  <!-- <origin xyz="0.022 0.202 0.01" rpy="0 0 0"/> -->
  <origin xyz="0.002 0.195 0.028" rpy="0 0 0"/>
  <parent link="base_link"/>
  <child link="left_wheel_link"/>
  <axis xyz="0.0 1.0 0.0"/>
</joint>
<joint name="laser_joint" type="fixed">
        <parent link="base_link"/>
        <child link="laser_frame"/>
        <origin xyz="0.25 0 0.205" rpy="0 0 0"/>
</joint>


<!-- <joint name="joint_1" type="continuous">
  <origin xyz="0.0 0.0 0.0" rpy="0 0 0"/>
  <parent link="base_link"/>
  <child link="link_1_1"/>
  <axis xyz="-0.0 -1.0 -0.0"/>
</joint>

<joint name="joint_2" type="continuous">
  <origin xyz="0.0 0.0 0.0" rpy="0 0 0"/>
  <parent link="base_link"/>
  <child link="link_2_1"/>
  <axis xyz="0.0 1.0 0.0"/>
</joint> -->
<material name="red">
    <color rgba="1 0 0 1"/>
</material>
</robot>
