<?xml version="1.0" encoding="utf-8"?>
<!-- This URDF was automatically created by SolidWorks to URDF Exporter! Originally created by Stephen Brawner (brawner@gmail.com) 
     Commit Version: 1.5.0-0-g9aa0fdb  Build Version: 1.5.7004.21443
     For more information, please see http://wiki.ros.org/sw_urdf_exporter -->
<robot
  name="amr" xmlns:xacro="http://www.ros.org/wiki/xacro">

<xacro:include filename="$(find amr_description)/urdf/materials.xacro" />
<xacro:include filename="$(find amr_description)/urdf/amr.trans" />
<xacro:include filename="$(find amr_description)/urdf/amr.gazebo" />

  <link name="base_link">
  <inertial>
      <origin rpy="0 0 0" xyz="0.000331566894459373 -1.38869584628603E-18 0.0226798732825691"/>
      <mass value="16.6607693249907"/>
      <inertia ixx="0.342900416454384" ixy="-0.00791208000000003" ixz="-4.11696589312513E-05" iyy="0.595999267514538" iyz="-2.06655190930544E-17" izz="0.933088946009388"/>
    </inertial>
    <visual>
      <origin
        xyz="0 0 0.045"
        rpy="0 0 0" />
      <geometry>
        <mesh
          filename="package://amr_description/meshes/base_link.STL" />
      </geometry>
      <collision>
       <origin
        xyz="0 0 0"
        rpy="0 0 0" />
      <geometry>
        <mesh
          filename="package://amr_description/meshes/base_link.STL" />
      </geometry>
      </collision>
      <material
        name="white">
      </material>
    </visual>
  </link>
    <!--link
    name="base_footprint">
  </link>
    <joint
    name="footprint_joint"
    type="fixed">
      <origin
      xyz="0 0 0.04"
      rpy="0 0 0" />
    <parent
      link="base_footprint" />
    <child
      link="base_link" />
  </joint> -->
  <link
    name="lw_link">
    <inertial>
      <origin rpy="0 0 0" xyz="1.90819582357449E-17 0 -0.0273880597014926"/>
      <mass value="1.34185276216454"/>
      <inertia ixx="0.00397939442139444" ixy="-2.16840434497101E-19" ixz="-5.79710388341049E-20" iyy="0.00397939442139444" iyz="1.23940974937118E-21" izz="0.00747907672941523"/>
    </inertial>
    <visual>
      <origin
        xyz="0 0 0"
        rpy="-1.5707963267949 0 0" />
      <geometry>
        <mesh
          filename="package://amr_description/meshes/lw_link.STL" />
      </geometry>
      <material
        name="red">
      </material>
    </visual>
  </link>
  <joint
    name="lw_joint"
    type="continuous">
      <origin
      xyz="0 0.225 0.1"
      rpy="0 0 0" />
    <parent
      link="base_link" />
    <child
      link="lw_link" />
    <axis
      xyz="0 1 0" />
    <safety_controller
      k_velocity="0" />
  </joint>
  <link
    name="rw_link">
    <inertial>
      <origin rpy="0 0 0" xyz="1.1106354187428E-17 0 -0.0273880597014926"/>
      <mass value="1.34185276216454"/>
      <inertia ixx="0.00397939442139445" ixy="-3.23472618749719E-35" ixz="-1.8026519749501E-21" iyy="0.00397939442139445" iyz="-1.7985063567581E-35" izz="0.00747907672941523"/>
    </inertial>
    <visual>
      <origin
        xyz="0 0 0"
        rpy="1.5707963267949 0 0" />
      <geometry>
        <mesh
          filename="package://amr_description/meshes/rw_link.STL" />
      </geometry>
      <material
        name="red">
      </material>
    </visual>
  </link>
  <joint
    name="rw_joint"
    type="continuous">
      <origin
      xyz="0 -0.225 0.1"
      rpy="0 0 0" />
    <parent
      link="base_link" />
    <child
      link="rw_link" />
    <axis
      xyz="0 1 0" />
    <safety_controller
      k_velocity="0" />
  </joint>

  <joint name="hokuyo_joint" type="fixed">
     <origin xyz="0.35 -0.28 0.09" rpy="0.0 0.0 -0.785"/>
    <parent link="base_link"/>
    <child link="hokuyo_link"/>
  </joint>

  <link name="hokuyo_link">
    <visual>
      <origin xyz="0 0 0" rpy="0 0 0"/>
      <geometry>
       <mesh filename="package://amr_description/meshes/hokuyo.dae" />
      </geometry>
    </visual>
  </link>

    <material name="black">
      <color rgba="0.007 0.007 0.007 1.0"/>
    </material>

    <material name="red">
      <color rgba="0.49693 0.01298 0.00518 1.0"/>
    </material>

    <material name="white">
      <color rgba="0.87962 0.8388 0.75294 1.0"/>
    </material>

</robot>
